Workbook

Sheet final-RA-to-framework-summary
B1: Framework ID | C1: F1 | D1: F2 | E1: F3 | F1: F4 | G1: F5 | H1: F6 | I1: F7 | J1: F8 | K1: F9 | L1: F10 | M1: F11 | N1: F12 | O1: F13 | P1: F14 | Q1: F15 | R1: F16 | S1: F17 | T1: F18
B2: Framework name | C2: Gymnasium | D2: PettingZoo | E2: Unity ML-Agents | F2: Isaac Gym | G2: Isaac Lab | H2: dm_control | I2: DeepMind Lab | J2: Arcade Learning Environment | K2: Jumanji | L2: Stable Baselines3 | M2: RL Baselines3 Zoo | N2: RLlib | O2: Acme | P2: MARLlib | Q2: BenchMARL | R2: Mava | S2: Dopamine | T2: Tianshou
A3: Component group | B3: Component | C3: towers2025gymnasium | D3: terry2021pettingzoo | E3: juliani2020 | F3: makoviychuk2021isaac | G3: mittal2025isaac | H3: tunyasuvunakool2020 | I3: beattie2016deepmind | J3: bellemare2013arcade | K3: bonnet2024jumanji | L3: stable-baselines3 | M3: rl-zoo3 | N3: liang2018rllib | O3: hoffman2020acme | P3: hu2022marllib | Q3: bettini2024benchmarl | R3: dekock2023mava | S3: castro18dopamine | T3: tianshou
A4: Experiment Orchestrator | B4: Experiment Orchestrator | C4: not implemented | D4: not implemented | E4: not implemented | F4: not implemented | G4: not implemented | H4: not implemented | I4: not implemented | J4: not implemented | K4: not implemented | L4: not implemented | M4: implicit | N4: not implemented | O4: not implemented | P4: not implemented | Q4: not implemented | R4: not implemented | S4: not implemented | T4: not implemented
A5: Experiment Orchestrator | B5: Experiment Manager | C5: not implemented | D5: not implemented | E5: implicit | F5: not implemented | G5: not implemented | H5: not implemented | I5: not implemented | J5: not implemented | K5: not implemented | L5: implicit | M5: explicit | N5: implicit | O5: implicit | P5: implicit | Q5: implicit | R5: implicit | S5: implicit | T5: explicit
A6: Experiment Orchestrator | B6: Hyperparameter Tuner | C6: not implemented | D6: not implemented | E6: not implemented | F6: not implemented | G6: not implemented | H6: not implemented | I6: not implemented | J6: not implemented | K6: not implemented | L6: not implemented | M6: external | N6: external | O6: not implemented | P6: external | Q6: not implemented | R6: not implemented | S6: not implemented | T6: not implemented
A7: Experiment Orchestrator | B7: Benchmark Manager | C7: not implemented | D7: not implemented | E7: not implemented | F7: not implemented | G7: not implemented | H7: not implemented | I7: not implemented | J7: not implemented | K7: not implemented | L7: not implemented | M7: not implemented | N7: not implemented | O7: not implemented | P7: not implemented | Q7: explicit | R7: not implemented | S7: not implemented | T7: not implemented
A8: Framework Orchestrator | B8: Framework Orchestrator | C8: not implemented | D8: not implemented | E8: implicit | F8: not implemented | G8: not implemented | H8: not implemented | I8: not implemented | J8: not implemented | K8: not implemented | L8: implicit | M8: external | N8: implicit | O8: implicit | P8: implicit | Q8: implicit | R8: implicit | S8: implicit | T8: explicit
A9: Framework Orchestrator | B9: Lifecycle Manager | C9: not implemented | D9: not implemented | E9: explicit | F9: not implemented | G9: not implemented | H9: not implemented | I9: not implemented | J9: not implemented | K9: not implemented | L9: implicit | M9: external | N9: explicit | O9: explicit | P9: external | Q9: implicit | R9: implicit | S9: implicit | T9: implicit
A10: Framework Orchestrator | B10: Configuration Manager | C10: not implemented | D10: not implemented | E10: not implemented | F10: not implemented | G10: external | H10: not implemented | I10: not implemented | J10: not implemented | K10: not implemented | L10: not implemented | M10: not implemented | N10: explicit | O10: not implemented | P10: external | Q10: external | R10: external | S10: external | T10: explicit
A11: Framework Orchestrator | B11: Multi-Agent Coordinator | C11: not implemented | D11: implicit | E11: explicit | F11: not implemented | G11: implicit | H11: not implemented | I11: not implemented | J11: not implemented | K11: not implemented | L11: not implemented | M11: not implemented | N11: implicit | O11: not implemented | P11: implicit | Q11: implicit | R11: not implemented | S11: not implemented | T11: implicit
A12: Framework Orchestrator | B12: Distributed Execution Coordinator | C12: not implemented | D12: not implemented | E12: not implemented | F12: not implemented | G12: not implemented | H12: not implemented | I12: not implemented | J12: not implemented | K12: not implemented | L12: not implemented | M12: not implemented | N12: external | O12: external | P12: external | Q12: not implemented | R12: implicit | S12: not implemented | T12: not implemented
A13: Agent | B13: Agent | C13: not implemented | D13: not implemented | E13: explicit | F13: not implemented | G13: not implemented | H13: not implemented | I13: not implemented | J13: not implemented | K13: not implemented | L13: explicit | M13: external | N13: explicit | O13: explicit | P13: external | Q13: explicit | R13: explicit | S13: explicit | T13: explicit
A14: Agent | B14: Function Approximator | C14: not implemented | D14: not implemented | E14: explicit | F14: not implemented | G14: not implemented | H14: not implemented | I14: not implemented | J14: not implemented | K14: not implemented | L14: explicit | M14: external | N14: explicit | O14: explicit | P14: external | Q14: explicit | R14: implicit | S14: implicit | T14: explicit
... A26: Monitoring & Visualization | B26: Reporter | C26: explicit | D26: explicit | E26: external | F26: external | G26: not implemented | H26: not implemented | I26: not implemented | J26: not implemented | K26: not implemented | L26: external | M26: explicit | N26: explicit | O26: not implemented | P26: external | Q26: external | R26: external | S26: external | T26: external

Sheet final-RA-to-framework-detail
A1: Framework ID | B1: Framework name | C1: Component | D1: Component status | E1: Link | F1: Code snippet | G1: Explanation | H1: External library
A2: {=INDEX('final-RA-to-framework-summary'!$C$1:$T$1, 1, INT((ROW(A1)-1)/23)+1)} -> F1 | B2: {=INDEX('final-RA-to-framework-summary'!$C$2:$T$2, 1, INT((ROW(B1)-1)/23)+1)} -> Gymnasium | C2: {=INDEX('final-RA-to-framework-summary'!$B$4:$B$26, MOD(ROW(A1)-1, 23)+1)} -> Experiment Orchestrator | D2: {=INDEX('final-RA-to-framework-summary'!$C$4:$Z$26, MOD(ROW(A1)-1, 23)+1, INT((ROW(A1)-1)/23)+1)} -> not implemented
A3: {=INDEX('final-RA-to-framework-summary'!$C$1:$T$1, 1, INT((ROW(A2)-1)/23)+1)} -> F1 | B3: {=INDEX('final-RA-to-framework-summary'!$C$2:$T$2, 1, INT((ROW(B2)-1)/23)+1)} -> Gymnasium | C3: {=INDEX('final-RA-to-framework-summary'!$B$4:$B$26, MOD(ROW(A2)-1, 23)+1)} -> Experiment Manager | D3: {=INDEX('final-RA-to-framework-summary'!$C$4:$Z$26, MOD(ROW(A2)-1, 23)+1, INT((ROW(A2)-1)/23)+1)} -> not implemented
A4: {=INDEX('final-RA-to-framework-summary'!$C$1:$T$1, 1, INT((ROW(A3)-1)/23)+1)} -> F1 | B4: {=INDEX('final-RA-to-framework-summary'!$C$2:$T$2, 1, INT((ROW(B3)-1)/23)+1)} -> Gymnasium | C4: {=INDEX('final-RA-to-framework-summary'!$B$4:$B$26, MOD(ROW(A3)-1, 23)+1)} -> Hyperparameter Tuner | D4: {=INDEX('final-RA-to-framework-summary'!$C$4:$Z$26, MOD(ROW(A3)-1, 23)+1, INT((ROW(A3)-1)/23)+1)} -> not implemented
A5: {=INDEX('final-RA-to-framework-summary'!$C$1:$T$1, 1, INT((ROW(A4)-1)/23)+1)} -> F1 | B5: {=INDEX('final-RA-to-framework-summary'!$C$2:$T$2, 1, INT((ROW(B4)-1)/23)+1)} -> Gymnasium | C5: {=INDEX('final-RA-to-framework-summary'!$B$4:$B$26, MOD(ROW(A4)-1, 23)+1)} -> Benchmark Manager | D5: {=INDEX('final-RA-to-framework-summary'!$C$4:$Z$26, MOD(ROW(A4)-1, 23)+1, INT((ROW(A4)-1)/23)+1)} -> not implemented
A6: {=INDEX('final-RA-to-framework-summary'!$C$1:$T$1, 1, INT((ROW(A5)-1)/23)+1)} -> F1 | B6: {=INDEX('final-RA-to-framework-summary'!$C$2:$T$2, 1, INT((ROW(B5)-1)/23)+1)} -> Gymnasium | C6: {=INDEX('final-RA-to-framework-summary'!$B$4:$B$26, MOD(ROW(A5)-1, 23)+1)} -> Framework Orchestrator | D6: {=INDEX('final-RA-to-framework-summary'!$C$4:$Z$26, MOD(ROW(A5)-1, 23)+1, INT((ROW(A5)-1)/23)+1)} -> not implemented
A7: {=INDEX('final-RA-to-framework-summary'!$C$1:$T$1, 1, INT((ROW(A6)-1)/23)+1)} -> F1 | B7: {=INDEX('final-RA-to-framework-summary'!$C$2:$T$2, 1, INT((ROW(B6)-1)/23)+1)} -> Gymnasium | C7: {=INDEX('final-RA-to-framework-summary'!$B$4:$B$26, MOD(ROW(A6)-1, 23)+1)} -> Lifecycle Manager | D7: {=INDEX('final-RA-to-framework-summary'!$C$4:$Z$26, MOD(ROW(A6)-1, 23)+1, INT((ROW(A6)-1)/23)+1)} -> not implemented
A8: {=INDEX('final-RA-to-framework-summary'!$C$1:$T$1, 1, INT((ROW(A7)-1)/23)+1)} -> F1 | B8: {=INDEX('final-RA-to-framework-summary'!$C$2:$T$2, 1, INT((ROW(B7)-1)/23)+1)} -> Gymnasium | C8: {=INDEX('final-RA-to-framework-summary'!$B$4:$B$26, MOD(ROW(A7)-1, 23)+1)} -> Configuration Manager | D8: {=INDEX('final-RA-to-framework-summary'!$C$4:$Z$26, MOD(ROW(A7)-1, 23)+1, INT((ROW(A7)-1)/23)+1)} -> not implemented
A9: {=INDEX('final-RA-to-framework-summary'!$C$1:$T$1, 1, INT((ROW(A8)-1)/23)+1)} -> F1 | B9: {=INDEX('final-RA-to-framework-summary'!$C$2:$T$2, 1, INT((ROW(B8)-1)/23)+1)} -> Gymnasium | C9: {=INDEX('final-RA-to-framework-summary'!$B$4:$B$26, MOD(ROW(A8)-1, 23)+1)} -> Multi-Agent Coordinator | D9: {=INDEX('final-RA-to-framework-summary'!$C$4:$Z$26, MOD(ROW(A8)-1, 23)+1, INT((ROW(A8)-1)/23)+1)} -> not implemented
A10: {=INDEX('final-RA-to-framework-summary'!$C$1:$T$1, 1, INT((ROW(A9)-1)/23)+1)} -> F1 | B10: {=INDEX('final-RA-to-framework-summary'!$C$2:$T$2, 1, INT((ROW(B9)-1)/23)+1)} -> Gymnasium | C10: {=INDEX('final-RA-to-framework-summary'!$B$4:$B$26, MOD(ROW(A9)-1, 23)+1)} -> Distributed Execution Coordinator | D10: {=INDEX('final-RA-to-framework-summary'!$C$4:$Z$26, MOD(ROW(A9)-1, 23)+1, INT((ROW(A9)-1)/23)+1)} -> not implemented
A11: {=INDEX('final-RA-to-framework-summary'!$C$1:$T$1, 1, INT((ROW(A10)-1)/23)+1)} -> F1 | B11: {=INDEX('final-RA-to-framework-summary'!$C$2:$T$2, 1, INT((ROW(B10)-1)/23)+1)} -> Gymnasium | C11: {=INDEX('final-RA-to-framework-summary'!$B$4:$B$26, MOD(ROW(A10)-1, 23)+1)} -> Agent | D11: {=INDEX('final-RA-to-framework-summary'!$C$4:$Z$26, MOD(ROW(A10)-1, 23)+1, INT((ROW(A10)-1)/23)+1)} -> not implemented
A12: {=INDEX('final-RA-to-framework-summary'!$C$1:$T$1, 1, INT((ROW(A11)-1)/23)+1)} -> F1 | B12: {=INDEX('final-RA-to-framework-summary'!$C$2:$T$2, 1, INT((ROW(B11)-1)/23)+1)} -> Gymnasium | C12: {=INDEX('final-RA-to-framework-summary'!$B$4:$B$26, MOD(ROW(A11)-1, 23)+1)} -> Function Approximator | D12: {=INDEX('final-RA-to-framework-summary'!$C$4:$Z$26, MOD(ROW(A11)-1, 23)+1, INT((ROW(A11)-1)/23)+1)} -> not implemented
A13: {=INDEX('final-RA-to-framework-summary'!$C$1:$T$1, 1, INT((ROW(A12)-1)/23)+1)} -> F1 | B13: {=INDEX('final-RA-to-framework-summary'!$C$2:$T$2, 1, INT((ROW(B12)-1)/23)+1)} -> Gymnasium | C13: {=INDEX('final-RA-to-framework-summary'!$B$4:$B$26, MOD(ROW(A12)-1, 23)+1)} -> Buffer | D13: {=INDEX('final-RA-to-framework-summary'!$C$4:$Z$26, MOD(ROW(A12)-1, 23)+1, INT((ROW(A12)-1)/23)+1)} -> not implemented
A14: {=INDEX('final-RA-to-framework-summary'!$C$1:$T$1, 1, INT((ROW(A13)-1)/23)+1)} -> F1 | B14: {=INDEX('final-RA-to-framework-summary'!$C$2:$T$2, 1, INT((ROW(B13)-1)/23)+1)} -> Gymnasium | C14: {=INDEX('final-RA-to-framework-summary'!$B$4:$B$26, MOD(ROW(A13)-1, 23)+1)} -> Learner | D14: {=INDEX('final-RA-to-framework-summary'!$C$4:$Z$26, MOD(ROW(A13)-1, 23)+1, INT((ROW(A13)-1)/23)+1)} -> not implemented
A15: {=INDEX('final-RA-to-framework-summary'!$C$1:$T$1, 1, INT((ROW(A14)-1)/23)+1)} -> F1 | B15: {=INDEX('final-RA-to-framework-summary'!$C$2:$T$2, 1, INT((ROW(B14)-1)/23)+1)} -> Gymnasium | C15: {=INDEX('final-RA-to-framework-summary'!$B$4:$B$26, MOD(ROW(A14)-1, 23)+1)} -> Environment | D15: {=INDEX('final-RA-to-framework-summary'!$C$4:$Z$26, MOD(ROW(A14)-1, 23)+1, INT((ROW(A14)-1)/23)+1)} -> explicit | E15: https://github.com/Farama-Foundation/Gymnasium/blob/main/gymnasium/core.py | F15: class Env(Generic[ObsType, ActType]): r"""The main Gymnasium class for implementing Reinforcement Learning Agents environments.
A16: {=INDEX('final-RA-to-framework-summary'!$C$1:$T$1, 1, INT((ROW(A15)-1)/23)+1)} -> F1 | B16: {=INDEX('final-RA-to-framework-summary'!$C$2:$T$2, 1, INT((ROW(B15)-1)/23)+1)} -> Gymnasium | C16: {=INDEX('final-RA-to-framework-summary'!$B$4:$B$26, MOD(ROW(A15)-1, 23)+1)} -> Environment Core | D16: {=INDEX('final-RA-to-framework-summary'!$C$4:$Z$26, MOD(ROW(A15)-1, 23)+1, INT((ROW(A15)-1)/23)+1)} -> explicit | E16: https://github.com/Farama-Foundation/Gymnasium/blob/main/gymnasium/core.py ; https://github.com/Farama-Foundation/Gymnasium/tree/main/gymnasium/envs | F16: class Env(Generic[ObsType, ActType]): r"""The main Gymnasium class for implementing Reinforcement Learning Agents environments. The class encapsulates an environment with arbitrary behind-the-scenes dynamics through the :meth:`step` and :meth:`reset` functions. An environment can be partially or fully observed by single agents. | G16: Action: each env’s step() to execute; Observation: step() reset() return observation value Reward: calculated inside each env’s step() IN envs/ implement list of envs
A17: {=INDEX('final-RA-to-framework-summary'!$C$1:$T$1, 1, INT((ROW(A16)-1)/23)+1)} -> F1 | B17: {=INDEX('final-RA-to-framework-summary'!$C$2:$T$2, 1, INT((ROW(B16)-1)/23)+1)} -> Gymnasium | C17: {=INDEX('final-RA-to-framework-summary'!$B$4:$B$26, MOD(ROW(A16)-1, 23)+1)} -> Simulator | D17: {=INDEX('final-RA-to-framework-summary'!$C$4:$Z$26, MOD(ROW(A16)-1, 23)+1, INT((ROW(A16)-1)/23)+1)} -> implicit | E17: Mujoco: https://github.com/Farama-Foundation/Gymnasium/blob/main/gymnasium/envs/mujoco/mujoco_env.py Box2D: https://github.com/Farama-Foundation/Gymnasium/blob/main/gymnasium/envs/box2d/bipedal_walker.py | F17: import mujoco import Box2D | G17: either merge into the pre-packaged environments or rely on external simulators
A18: {=INDEX('final-RA-to-framework-summary'!$C$1:$T$1, 1, INT((ROW(A17)-1)/23)+1)} -> F1 | B18: {=INDEX('final-RA-to-framework-summary'!$C$2:$T$2, 1, INT((ROW(B17)-1)/23)+1)} -> Gymnasium | C18: {=INDEX('final-RA-to-framework-summary'!$B$4:$B$26, MOD(ROW(A17)-1, 23)+1)} -> Simulator Adapter | D18: {=INDEX('final-RA-to-framework-summary'!$C$4:$Z$26, MOD(ROW(A17)-1, 23)+1, INT((ROW(A17)-1)/23)+1)} -> implicit | E18: https://github.com/Farama-Foundation/Gymnasium/blob/main/gymnasium/envs/mujoco/mujoco_env.py | F18: gymnasium/envs/mujoco/mujoco_env.py class MujocoEnv(gym.Env): """Superclass for MuJoCo based environments.""" _initialize_simulation, _step_mujoco_simulation | G18: many, depends on different simulator, for example in the link, function call to the Mujoco simulator
A19: {=INDEX('final-RA-to-framework-summary'!$C$1:$T$1, 1, INT((ROW(A18)-1)/23)+1)} -> F1 | B19: {=INDEX('final-RA-to-framework-summary'!$C$2:$T$2, 1, INT((ROW(B18)-1)/23)+1)} -> Gymnasium | C19: {=INDEX('final-RA-to-framework-summary'!$B$4:$B$26, MOD(ROW(A18)-1, 23)+1)} -> Checkpoint Manager | D19: {=INDEX('final-RA-to-framework-summary'!$C$4:$Z$26, MOD(ROW(A18)-1, 23)+1, INT((ROW(A18)-1)/23)+1)} -> not implemented
A20: {=INDEX('final-RA-to-framework-summary'!$C$1:$T$1, 1, INT((ROW(A19)-1)/23)+1)} -> F1 | B20: {=INDEX('final-RA-to-framework-summary'!$C$2:$T$2, 1, INT((ROW(B19)-1)/23)+1)} -> Gymnasium | C20: {=INDEX('final-RA-to-framework-summary'!$B$4:$B$26, MOD(ROW(A19)-1, 23)+1)} -> Environment Parameter Manager | D20: {=INDEX('final-RA-to-framework-summary'!$C$4:$Z$26, MOD(ROW(A19)-1, 23)+1, INT((ROW(A19)-1)/23)+1)} -> not implemented
A21: {=INDEX('final-RA-to-framework-summary'!$C$1:$T$1, 1, INT((ROW(A20)-1)/23)+1)} -> F1 | B21: {=INDEX('final-RA-to-framework-summary'!$C$2:$T$2, 1, INT((ROW(B20)-1)/23)+1)} -> Gymnasium | C21: {=INDEX('final-RA-to-framework-summary'!$B$4:$B$26, MOD(ROW(A20)-1, 23)+1)} -> Renderer | D21: {=INDEX('final-RA-to-framework-summary'!$C$4:$Z$26, MOD(ROW(A20)-1, 23)+1, INT((ROW(A20)-1)/23)+1)} -> explicit | E21: https://github.com/Farama-Foundation/Gymnasium/blob/main/gymnasium/envs/mujoco/mujoco_rendering.py ; https://github.com/Farama-Foundation/Gymnasium/blob/main/gymnasium/wrappers/vector/rendering.py | F21: BaseRender: Render context superclass for offscreen and window rendering. OffScreenViewer(BaseRender): Offscreen rendering class with opengl context. ----- class HumanRendering(VectorWrapper, gym.utils.RecordConstructorArgs): Adds support for Human-based Rendering for Vector-based environments.
A22: {=INDEX('final-RA-to-framework-summary'!$C$1:$T$1, 1, INT((ROW(A21)-1)/23)+1)} -> F1 | B22: {=INDEX('final-RA-to-framework-summary'!$C$2:$T$2, 1, INT((ROW(B21)-1)/23)+1)} -> Gymnasium | C22: {=INDEX('final-RA-to-framework-summary'!$B$4:$B$26, MOD(ROW(A21)-1, 23)+1)} -> Recorder | D22: {=INDEX('final-RA-to-framework-summary'!$C$4:$Z$26, MOD(ROW(A21)-1, 23)+1, INT((ROW(A21)-1)/23)+1)} -> explicit | E22: https://github.com/Farama-Foundation/Gymnasium/blob/main/gymnasium/wrappers/vector/rendering.py ; https://github.com/Farama-Foundation/Gymnasium/blob/main/gymnasium/utils/save_video.py | F22: class RecordVideo: Adds support for video recording for Vector-based environments. ----- def save_video(): Save videos from rendering frames. -- call frames=env.render()
A23: {=INDEX('final-RA-to-framework-summary'!$C$1:$T$1, 1, INT((ROW(A22)-1)/23)+1)} -> F1 | B23: {=INDEX('final-RA-to-framework-summary'!$C$2:$T$2, 1, INT((ROW(B22)-1)/23)+1)} -> Gymnasium | C23: {=INDEX('final-RA-to-framework-summary'!$B$4:$B$26, MOD(ROW(A22)-1, 23)+1)} -> Logger | D23: {=INDEX('final-RA-to-framework-summary'!$C$4:$Z$26, MOD(ROW(A22)-1, 23)+1, INT((ROW(A22)-1)/23)+1)} -> explicit | E23: https://github.com/Farama-Foundation/Gymnasium/blob/main/gymnasium/logger.py ; https://github.com/Farama-Foundation/Gymnasium/blob/main/gymnasium/wrappers/vector/common.py | F23: Set of functions for logging messages. ----- class RecordEpisodeStatistics(VectorWrapper): This wrapper will keep track of cumulative rewards and episode lengths. the most recent rewards and episode lengths are stored in buffers that can be accessed via :attr:`wrapped_env.return_queue` and :attr:`wrapped_env.length_queue` respectively.
A24: {=INDEX('final-RA-to-framework-summary'!$C$1:$T$1, 1, INT((ROW(A23)-1)/23)+1)} -> F1 | B24: {=INDEX('final-RA-to-framework-summary'!$C$2:$T$2, 1, INT((ROW(B23)-1)/23)+1)} -> Gymnasium | C24: {=INDEX('final-RA-to-framework-summary'!$B$4:$B$26, MOD(ROW(A23)-1, 23)+1)} -> Reporter | D24: {=INDEX('final-RA-to-framework-summary'!$C$4:$Z$26, MOD(ROW(A23)-1, 23)+1, INT((ROW(A23)-1)/23)+1)} -> explicit | E24: https://github.com/Farama-Foundation/Gymnasium/blob/main/gymnasium/wrappers/vector/common.py | F24: class RecordEpisodeStatistics(VectorWrapper): This wrapper will keep track of cumulative rewards and episode lengths. the most recent rewards and episode lengths are stored in buffers that can be accessed via :attr:`wrapped_env.return_queue` and :attr:`wrapped_env.length_queue` respectively.
A25: {=INDEX('final-RA-to-framework-summary'!$C$1:$T$1, 1, INT((ROW(A24)-1)/23)+1)} -> F2 | B25: {=INDEX('final-RA-to-framework-summary'!$C$2:$T$2, 1, INT((ROW(B24)-1)/23)+1)} -> PettingZoo | C25: {=INDEX('final-RA-to-framework-summary'!$B$4:$B$26, MOD(ROW(A24)-1, 23)+1)} -> Experiment Orchestrator | D25: {=INDEX('final-RA-to-framework-summary'!$C$4:$Z$26, MOD(ROW(A24)-1, 23)+1, INT((ROW(A24)-1)/23)+1)} -> not implemented
A26: {=INDEX('final-RA-to-framework-summary'!$C$1:$T$1, 1, INT((ROW(A25)-1)/23)+1)} -> F2 | B26: {=INDEX('final-RA-to-framework-summary'!$C$2:$T$2, 1, INT((ROW(B25)-1)/23)+1)} -> PettingZoo | C26: {=INDEX('final-RA-to-framework-summary'!$B$4:$B$26, MOD(ROW(A25)-1, 23)+1)} -> Experiment Manager | D26: {=INDEX('final-RA-to-framework-summary'!$C$4:$Z$26, MOD(ROW(A25)-1, 23)+1, INT((ROW(A25)-1)/23)+1)} -> not implemented
A27: {=INDEX('final-RA-to-framework-summary'!$C$1:$T$1, 1, INT((ROW(A26)-1)/23)+1)} -> F2 | B27: {=INDEX('final-RA-to-framework-summary'!$C$2:$T$2, 1, INT((ROW(B26)-1)/23)+1)} -> PettingZoo | C27: {=INDEX('final-RA-to-framework-summary'!$B$4:$B$26, MOD(ROW(A26)-1, 23)+1)} -> Hyperparameter Tuner | D27: {=INDEX('final-RA-to-framework-summary'!$C$4:$Z$26, MOD(ROW(A26)-1, 23)+1, INT((ROW(A26)-1)/23)+1)} -> not implemented
A28: {=INDEX('final-RA-to-framework-summary'!$C$1:$T$1, 1, INT((ROW(A27)-1)/23)+1)} -> F2 | B28: {=INDEX('final-RA-to-framework-summary'!$C$2:$T$2, 1, INT((ROW(B27)-1)/23)+1)} -> PettingZoo | C28: {=INDEX('final-RA-to-framework-summary'!$B$4:$B$26, MOD(ROW(A27)-1, 23)+1)} -> Benchmark Manager | D28: {=INDEX('final-RA-to-framework-summary'!$C$4:$Z$26, MOD(ROW(A27)-1, 23)+1, INT((ROW(A27)-1)/23)+1)} -> not implemented
A29: {=INDEX('final-RA-to-framework-summary'!$C$1:$T$1, 1, INT((ROW(A28)-1)/23)+1)} -> F2 | B29: {=INDEX('final-RA-to-framework-summary'!$C$2:$T$2, 1, INT((ROW(B28)-1)/23)+1)} -> PettingZoo | C29: {=INDEX('final-RA-to-framework-summary'!$B$4:$B$26, MOD(ROW(A28)-1, 23)+1)} -> Framework Orchestrator | D29: {=INDEX('final-RA-to-framework-summary'!$C$4:$Z$26, MOD(ROW(A28)-1, 23)+1, INT((ROW(A28)-1)/23)+1)} -> not implemented
A30: {=INDEX('final-RA-to-framework-summary'!$C$1:$T$1, 1, INT((ROW(A29)-1)/23)+1)} -> F2 | B30: {=INDEX('final-RA-to-framework-summary'!$C$2:$T$2, 1, INT((ROW(B29)-1)/23)+1)} -> PettingZoo | C30: {=INDEX('final-RA-to-framework-summary'!$B$4:$B$26, MOD(ROW(A29)-1, 23)+1)} -> Lifecycle Manager | D30: {=INDEX('final-RA-to-framework-summary'!$C$4:$Z$26, MOD(ROW(A29)-1, 23)+1, INT((ROW(A29)-1)/23)+1)} -> not implemented
A31: {=INDEX('final-RA-to-framework-summary'!$C$1:$T$1, 1, INT((ROW(A30)-1)/23)+1)} -> F2 | B31: {=INDEX('final-RA-to-framework-summary'!$C$2:$T$2, 1, INT((ROW(B30)-1)/23)+1)} -> PettingZoo | C31: {=INDEX('final-RA-to-framework-summary'!$B$4:$B$26, MOD(ROW(A30)-1, 23)+1)} -> Configuration Manager | D31: {=INDEX('final-RA-to-framework-summary'!$C$4:$Z$26, MOD(ROW(A30)-1, 23)+1, INT((ROW(A30)-1)/23)+1)} -> not implemented
A32: {=INDEX('final-RA-to-framework-summary'!$C$1:$T$1, 1, INT((ROW(A31)-1)/23)+1)} -> F2 | B32: {=INDEX('final-RA-to-framework-summary'!$C$2:$T$2, 1, INT((ROW(B31)-1)/23)+1)} -> PettingZoo | C32: {=INDEX('final-RA-to-framework-summary'!$B$4:$B$26, MOD(ROW(A31)-1, 23)+1)} -> Multi-Agent Coordinator | D32: {=INDEX('final-RA-to-framework-summary'!$C$4:$Z$26, MOD(ROW(A31)-1, 23)+1, INT((ROW(A31)-1)/23)+1)} -> implicit | E32: https://github.com/Farama-Foundation/PettingZoo/blob/master/pettingzoo/utils/agent_selector.py | F32: class AgentSelector: """Outputs an agent in the given order whenever agent_select is called. Can reinitialize to a new order. | G32: The agent selector utility allows for easy cycling of agents in an AEC environment. At any time it can be reset or reinitialized with a new order, allowing for changes in turn order or handling a dynamic number of agents. Also, for Parallel: steps every live agent at once actions provided as {agent_id: action} dict (Parallel env implementation logic)
A33: {=INDEX('final-RA-to-framework-summary'!$C$1:$T$1, 1, INT((ROW(A32)-1)/23)+1)} -> F2 | B33: {=INDEX('final-RA-to-framework-summary'!$C$2:$T$2, 1, INT((ROW(B32)-1)/23)+1)} -> PettingZoo | C33: {=INDEX('final-RA-to-framework-summary'!$B$4:$B$26, MOD(ROW(A32)-1, 23)+1)} -> Distributed Execution Coordinator | D33: {=INDEX('final-RA-to-framework-summary'!$C$4:$Z$26, MOD(ROW(A32)-1, 23)+1, INT((ROW(A32)-1)/23)+1)} -> not implemented
A34: {=INDEX('final-RA-to-framework-summary'!$C$1:$T$1, 1, INT((ROW(A33)-1)/23)+1)} -> F2 | B34: {=INDEX('final-RA-to-framework-summary'!$C$2:$T$2, 1, INT((ROW(B33)-1)/23)+1)} -> PettingZoo | C34: {=INDEX('final-RA-to-framework-summary'!$B$4:$B$26, MOD(ROW(A33)-1, 23)+1)} -> Agent | D34: {=INDEX('final-RA-to-framework-summary'!$C$4:$Z$26, MOD(ROW(A33)-1, 23)+1, INT((ROW(A33)-1)/23)+1)} -> not implemented
A35: {=INDEX('final-RA-to-framework-summary'!$C$1:$T$1, 1, INT((ROW(A34)-1)/23)+1)} -> F2 | B35: {=INDEX('final-RA-to-framework-summary'!$C$2:$T$2, 1, INT((ROW(B34)-1)/23)+1)} -> PettingZoo | C35: {=INDEX('final-RA-to-framework-summary'!$B$4:$B$26, MOD(ROW(A34)-1, 23)+1)} -> Function Approximator | D35: {=INDEX('final-RA-to-framework-summary'!$C$4:$Z$26, MOD(ROW(A34)-1, 23)+1, INT((ROW(A34)-1)/23)+1)} -> not implemented
A36: {=INDEX('final-RA-to-framework-summary'!$C$1:$T$1, 1, INT((ROW(A35)-1)/23)+1)} -> F2 | B36: {=INDEX('final-RA-to-framework-summary'!$C$2:$T$2, 1, INT((ROW(B35)-1)/23)+1)} -> PettingZoo | C36: {=INDEX('final-RA-to-framework-summary'!$B$4:$B$26, MOD(ROW(A35)-1, 23)+1)} -> Buffer | D36: {=INDEX('final-RA-to-framework-summary'!$C$4:$Z$26, MOD(ROW(A35)-1, 23)+1, INT((ROW(A35)-1)/23)+1)} -> not implemented
A37: {=INDEX('final-RA-to-framework-summary'!$C$1:$T$1, 1, INT((ROW(A36)-1)/23)+1)} -> F2 | B37: {=INDEX('final-RA-to-framework-summary'!$C$2:$T$2, 1, INT((ROW(B36)-1)/23)+1)} -> PettingZoo | C37: {=INDEX('final-RA-to-framework-summary'!$B$4:$B$26, MOD(ROW(A36)-1, 23)+1)} -> Learner | D37: {=INDEX('final-RA-to-framework-summary'!$C$4:$Z$26, MOD(ROW(A36)-1, 23)+1, INT((ROW(A36)-1)/23)+1)} -> not implemented
A38: {=INDEX('final-RA-to-framework-summary'!$C$1:$T$1, 1, INT((ROW(A37)-1)/23)+1)} -> F2 | B38: {=INDEX('final-RA-to-framework-summary'!$C$2:$T$2, 1, INT((ROW(B37)-1)/23)+1)} -> PettingZoo | C38: {=INDEX('final-RA-to-framework-summary'!$B$4:$B$26, MOD(ROW(A37)-1, 23)+1)} -> Environment | D38: {=INDEX('final-RA-to-framework-summary'!$C$4:$Z$26, MOD(ROW(A37)-1, 23)+1, INT((ROW(A37)-1)/23)+1)} -> explicit | E38: https://github.com/Farama-Foundation/PettingZoo/blob/master/pettingzoo/utils/env.py | F38: class AECEnv(Generic[AgentID, ObsType, ActionType]): """The AECEnv steps agents one at a time. class ParallelEnv(Generic[AgentID, ObsType, ActionType]): """Parallel environment class.
A39: {=INDEX('final-RA-to-framework-summary'!$C$1:$T$1, 1, INT((ROW(A38)-1)/23)+1)} -> F2 | B39: {=INDEX('final-RA-to-framework-summary'!$C$2:$T$2, 1, INT((ROW(B38)-1)/23)+1)} -> PettingZoo | C39: {=INDEX('final-RA-to-framework-summary'!$B$4:$B$26, MOD(ROW(A38)-1, 23)+1)} -> Environment Core | D39: {=INDEX('final-RA-to-framework-summary'!$C$4:$Z$26, MOD(ROW(A38)-1, 23)+1, INT((ROW(A38)-1)/23)+1)} -> explicit | E39: https://github.com/Farama-Foundation/PettingZoo/blob/master/pettingzoo/utils/env.py | F39: AECEnv, ParallelEnv | G39: Action: In each env’s step() to execute; Observation: Inside each env’s observe(agent) method (AEC) or in its step() return (Parallel) Reward: Inside each env’s step() internally, the env keeps a per-agent env.rewards[agent] dict that accumulates increments between that agent’s turn env.last() method provides cumulative rewards since agent's last action for current agent
A40: {=INDEX('final-RA-to-framework-summary'!$C$1:$T$1, 1, INT((ROW(A39)-1)/23)+1)} -> F2 | B40: {=INDEX('final-RA-to-framework-summary'!$C$2:$T$2, 1, INT((ROW(B39)-1)/23)+1)} -> PettingZoo | C40: {=INDEX('final-RA-to-framework-summary'!$B$4:$B$26, MOD(ROW(A39)-1, 23)+1)} -> Simulator | D40: {=INDEX('final-RA-to-framework-summary'!$C$4:$Z$26, MOD(ROW(A39)-1, 23)+1, INT((ROW(A39)-1)/23)+1)} -> implicit | E40: https://github.com/Farama-Foundation/PettingZoo/blob/master/pettingzoo/mpe/_mpe_utils/core.py | F40: class World: # multi-agent world def __init__(self): # list of agents and entities (can change at execution-time!) self.agents = [] self.landmarks = [] # communication channel dimensionality self.dim_c = 0 # position dimensionality self.dim_p = 2 # color dimensionality self.dim_color = 3 # simulation timestep self.dt = 0.1 # physical damping self.damping = 0.25 # contact response parameters self.contact_force = 1e2 self.contact_margin = 1e-3 # update state of the world def step(self): # set actions for scripted agents for agent in self.scripted_agents: agent.action = agent.action_callback(agent, self) # gather forces applied to entities p_force = [None] * len(self.entities) # apply agent physical controls p_force = self.apply_action_force(p_force) # apply environment forces p_force = self.apply_environment_force(p_force) # integrate physical state self.integrate_state(p_force) # update agent state for agent in self.agents: self.update_agent_state(agent) | G40: Atari: ALE (Stella) via ale-py; MPE: lightweight physics in Python; classic: board-game logic in Python butterfly: custom simulators. For example, here it's do simulation step
...
